{"priority": "minor", "kind": "bug", "repository": {"links": {"self": {"href": "data/repositories/hoffmanlab/genomedata.json"}, "html": {"href": "#!/hoffmanlab/genomedata"}, "avatar": {"href": "data/bytebucket.org/ravatar/{78038659-1199-46ff-9d0a-675c62f89d60}ts=python"}}, "type": "repository", "name": "genomedata", "full_name": "hoffmanlab/genomedata", "uuid": "{78038659-1199-46ff-9d0a-675c62f89d60}"}, "links": {"attachments": {"href": "data/repositories/hoffmanlab/genomedata/issues/12/attachments_page=1.json"}, "self": {"href": "data/repositories/hoffmanlab/genomedata/issues/12.json"}, "watch": {"href": "https://api.bitbucket.org/2.0/repositories/hoffmanlab/genomedata/issues/12/watch"}, "comments": {"href": "data/repositories/hoffmanlab/genomedata/issues/12/comments_page=1.json"}, "html": {"href": "#!/hoffmanlab/genomedata/issues/12/concomitant-access-of-a-single-genomedata"}, "vote": {"href": "https://api.bitbucket.org/2.0/repositories/hoffmanlab/genomedata/issues/12/vote"}}, "reporter": {"display_name": "Coby Viner", "uuid": "{5c0277b2-d18f-432a-9ff0-3377d3063bd6}", "links": {"self": {"href": "https://api.bitbucket.org/2.0/users/%7B5c0277b2-d18f-432a-9ff0-3377d3063bd6%7D"}, "html": {"href": "https://bitbucket.org/%7B5c0277b2-d18f-432a-9ff0-3377d3063bd6%7D/"}, "avatar": {"href": "data/secure.gravatar.com/avatar/30ee4699432a3591c043fbe3d4bff771d=httpsavatar-management--avatars.us-west-2.prod.public.atl-paas.netinitialsCV-5.png"}}, "nickname": "cviner2", "type": "user", "account_id": "557058:278c659b-177a-486c-bf20-6982986d7e43"}, "title": "Concomitant access of a single Genomedata archive can lead to undefined behaviour", "component": null, "votes": 0, "watches": 3, "content": {"raw": "If any more than a small number of processes attempt to read data from the same archive, undefined behaviour can result. During an attempt to have approximately 100 processes reading from a single archive, only about 10% had any success, and of those 10%, most resulting files had missing data, despite not appearing to have caused any error to be output.\r\n\r\nIn particular, errors resembling the following frequently result:\r\n\r\n```\r\n#!text\r\nTraceback (most recent call last):\r\n  File \"/home/cviner/cytomod/cytomod/src/cytomod.py\", line 433, in <module>\r\n    with Genome(genomeDataArchive) as genome:\r\n  File \"/home/cviner/arch/Linux-i686/lib/python2.7/genomedata-1.3.3-py2.7.egg/genomedata/__init__.py\", line 151, in __init__\r\n    format_version = self.format_version\r\n  File \"/home/cviner/arch/Linux-i686/lib/python2.7/genomedata-1.3.3-py2.7.egg/genomedata/__init__.py\", line 427, in format_version\r\n    for chromosome in chromosomes)\r\n  File \"/home/cviner/arch/Linux-i686/lib/python2.7/genomedata-1.3.3-py2.7.egg/genomedata/__init__.py\", line 426, in <genexpr>\r\n    assert all(res == chromosome._format_version\r\n  File \"/home/cviner/arch/Linux-i686/lib/python2.7/genomedata-1.3.3-py2.7.egg/genomedata/__init__.py\", line 179, in __iter__\r\n    yield self[filepath.namebase]\r\n  File \"/home/cviner/arch/Linux-i686/lib/python2.7/genomedata-1.3.3-py2.7.egg/genomedata/__init__.py\", line 212, in __getitem__\r\n    *self.args, **self.kwargs)\r\n  File \"/home/cviner/arch/Linux-i686/lib/python2.7/genomedata-1.3.3-py2.7.egg/genomedata/__init__.py\", line 594, in _fromfilename\r\n    h5file = _open_file(filepath, mode=mode, *args, **kwargs)\r\n  File \"/home/cviner/arch/Linux-i686/lib/python2.7/genomedata-1.3.3-py2.7.egg/genomedata/__init__.py\", line 67, in _open_file\r\n    return openFile(*args, **kwargs)\r\n  File \"/home/cviner/arch/Linux-i686/lib/python2.7/tables/file.py\", line 230, in openFile\r\n    return File(filename, mode, title, rootUEP, filters, **kwargs)\r\n  File \"/home/cviner/arch/Linux-i686/lib/python2.7/tables/file.py\", line 495, in __init__\r\n    self._g_new(filename, mode, **params)\r\n  File \"hdf5Extension.pyx\", line 317, in tables.hdf5Extension.File._g_new (tables/hdf5Extension.c:3039)\r\ntables.exceptions.HDF5ExtError: HDF5 error back trace\r\n\r\n  File \"../../src/H5F.c\", line 1585, in H5Fopen\r\n    unable to open file\r\n  File \"../../src/H5F.c\", line 1274, in H5F_open\r\n    unable to open file: time = Thu Aug 21 12:22:07 2014\r\n, name = '/home/cviner/mordor_home/cytomod/experiments/linked-2014-08-18-K562_ModGenome_kV1/archive/chr22.genomedata', tent_flags = 0\r\n  File \"../../src/H5FD.c\", line 987, in H5FD_open\r\n    open failed\r\n  File \"../../src/H5FDsec2.c\", line 343, in H5FD_sec2_open\r\n    unable to open file: name = '/home/cviner/mordor_home/cytomod/experiments/linked-2014-08-18-K562_ModGenome_kV1/archive/chr22.genomedata', errno = 1, error message = 'Operation not permitted', flags = 0, o_flags = 0\r\n\r\nEnd of HDF5 error back trace\r\n```\r\n\r\nIdeally, parallel read access should depend only upon underlying OS/file-system limitations. Alternatively, an archive locking mechanism could be instituted to prevent this from occurring.", "markup": "markdown", "html": "<p>If any more than a small number of processes attempt to read data from the same archive, undefined behaviour can result. During an attempt to have approximately 100 processes reading from a single archive, only about 10% had any success, and of those 10%, most resulting files had missing data, despite not appearing to have caused any error to be output.</p>\n<p>In particular, errors resembling the following frequently result:</p>\n<div class=\"codehilite language-text\"><pre><span></span>Traceback (most recent call last):\n  File &quot;/home/cviner/cytomod/cytomod/src/cytomod.py&quot;, line 433, in &lt;module&gt;\n    with Genome(genomeDataArchive) as genome:\n  File &quot;/home/cviner/arch/Linux-i686/lib/python2.7/genomedata-1.3.3-py2.7.egg/genomedata/__init__.py&quot;, line 151, in __init__\n    format_version = self.format_version\n  File &quot;/home/cviner/arch/Linux-i686/lib/python2.7/genomedata-1.3.3-py2.7.egg/genomedata/__init__.py&quot;, line 427, in format_version\n    for chromosome in chromosomes)\n  File &quot;/home/cviner/arch/Linux-i686/lib/python2.7/genomedata-1.3.3-py2.7.egg/genomedata/__init__.py&quot;, line 426, in &lt;genexpr&gt;\n    assert all(res == chromosome._format_version\n  File &quot;/home/cviner/arch/Linux-i686/lib/python2.7/genomedata-1.3.3-py2.7.egg/genomedata/__init__.py&quot;, line 179, in __iter__\n    yield self[filepath.namebase]\n  File &quot;/home/cviner/arch/Linux-i686/lib/python2.7/genomedata-1.3.3-py2.7.egg/genomedata/__init__.py&quot;, line 212, in __getitem__\n    *self.args, **self.kwargs)\n  File &quot;/home/cviner/arch/Linux-i686/lib/python2.7/genomedata-1.3.3-py2.7.egg/genomedata/__init__.py&quot;, line 594, in _fromfilename\n    h5file = _open_file(filepath, mode=mode, *args, **kwargs)\n  File &quot;/home/cviner/arch/Linux-i686/lib/python2.7/genomedata-1.3.3-py2.7.egg/genomedata/__init__.py&quot;, line 67, in _open_file\n    return openFile(*args, **kwargs)\n  File &quot;/home/cviner/arch/Linux-i686/lib/python2.7/tables/file.py&quot;, line 230, in openFile\n    return File(filename, mode, title, rootUEP, filters, **kwargs)\n  File &quot;/home/cviner/arch/Linux-i686/lib/python2.7/tables/file.py&quot;, line 495, in __init__\n    self._g_new(filename, mode, **params)\n  File &quot;hdf5Extension.pyx&quot;, line 317, in tables.hdf5Extension.File._g_new (tables/hdf5Extension.c:3039)\ntables.exceptions.HDF5ExtError: HDF5 error back trace\n\n  File &quot;../../src/H5F.c&quot;, line 1585, in H5Fopen\n    unable to open file\n  File &quot;../../src/H5F.c&quot;, line 1274, in H5F_open\n    unable to open file: time = Thu Aug 21 12:22:07 2014\n, name = &#39;/home/cviner/mordor_home/cytomod/experiments/linked-2014-08-18-K562_ModGenome_kV1/archive/chr22.genomedata&#39;, tent_flags = 0\n  File &quot;../../src/H5FD.c&quot;, line 987, in H5FD_open\n    open failed\n  File &quot;../../src/H5FDsec2.c&quot;, line 343, in H5FD_sec2_open\n    unable to open file: name = &#39;/home/cviner/mordor_home/cytomod/experiments/linked-2014-08-18-K562_ModGenome_kV1/archive/chr22.genomedata&#39;, errno = 1, error message = &#39;Operation not permitted&#39;, flags = 0, o_flags = 0\n\nEnd of HDF5 error back trace\n</pre></div>\n\n\n<p>Ideally, parallel read access should depend only upon underlying OS/file-system limitations. Alternatively, an archive locking mechanism could be instituted to prevent this from occurring.</p>", "type": "rendered"}, "assignee": {"display_name": "Eric Roberts", "uuid": "{cd8c1fe0-28ca-45fb-8ef9-48090b42bb80}", "links": {"self": {"href": "https://api.bitbucket.org/2.0/users/%7Bcd8c1fe0-28ca-45fb-8ef9-48090b42bb80%7D"}, "html": {"href": "https://bitbucket.org/%7Bcd8c1fe0-28ca-45fb-8ef9-48090b42bb80%7D/"}, "avatar": {"href": "data/secure.gravatar.com/avatar/17548d71dfb29d015b880f48cfc01ca3d=httpsavatar-management--avatars.us-west-2.prod.public.atl-paas.netinitialsER-5.png"}}, "nickname": "ericr86", "type": "user", "account_id": "557058:c80ca578-03a1-4ac6-b3ee-50372a3fceee"}, "state": "invalid", "version": null, "edited_on": null, "created_on": "2014-08-21T17:34:24.918969+00:00", "milestone": null, "updated_on": "2014-08-22T01:19:48.238173+00:00", "type": "issue", "id": 12}