{"priority": "trivial", "kind": "enhancement", "repository": {"links": {"self": {"href": "data/repositories/hoffmanlab/genomedata.json"}, "html": {"href": "#!/hoffmanlab/genomedata"}, "avatar": {"href": "data/bytebucket.org/ravatar/{78038659-1199-46ff-9d0a-675c62f89d60}ts=python"}}, "type": "repository", "name": "genomedata", "full_name": "hoffmanlab/genomedata", "uuid": "{78038659-1199-46ff-9d0a-675c62f89d60}"}, "links": {"attachments": {"href": "data/repositories/hoffmanlab/genomedata/issues/14/attachments_page=1.json"}, "self": {"href": "data/repositories/hoffmanlab/genomedata/issues/14.json"}, "watch": {"href": "https://api.bitbucket.org/2.0/repositories/hoffmanlab/genomedata/issues/14/watch"}, "comments": {"href": "data/repositories/hoffmanlab/genomedata/issues/14/comments_page=1.json"}, "html": {"href": "#!/hoffmanlab/genomedata/issues/14/more-friendly-error-message-in-genomedata"}, "vote": {"href": "https://api.bitbucket.org/2.0/repositories/hoffmanlab/genomedata/issues/14/vote"}}, "reporter": null, "title": "More friendly error message in genomedata-load", "component": null, "votes": 0, "watches": 1, "content": {"raw": "While incorrectly creating a genomedata archive, a non-descript error message was reported. A more useful error message should indicate what went wrong.\r\n\r\nThe following command and problem was reported:\r\n\r\n```\r\ngenomedata-load \u2013s sequence1.fa \u2013s sequence2.fa \u2013s sequence3.fa \u2013s sequence4.fa \u2013s sequence5.fa \u2013s sequence6.fa \u2013s sequence7.fa \u2013s sequence8.fa \u2013t track1=signal1.wigFix \u2013t track2=signal2. wigFix \u2013t track3=signal3. wigFix \u2013t track4=signal4. wigFix \u2013t track5=signal5. wigFix \u2013t track6=signal6. wigFix \u2013t track7=signal7. wigFix \u2013t track8=signal8. wigFix gtest\r\n```\r\n\r\nAnd I got the following message:\r\n\r\n```\r\nError creating genomedata.\r\n\r\nTraceback (most recent call last):\r\n\r\n  File \"/usr/bin/genomedata-load\", line 9, in <module>\r\n\r\n    load_entry_point('genomedata==1.3.5', 'console_scripts', 'genomedata-load')()\r\n\r\n  File \"/usr/lib/python2.6/site-packages/genomedata/load_genomedata.py\", line 276, in main\r\n\r\n    seqfile_type=options.seqfile_type, **kwargs)\r\n\r\n  File \"/usr/lib/python2.6/site-packages/genomedata/load_genomedata.py\", line 100, in load_genomedata\r\n\r\n    seqfile_type=seqfile_type)\r\n\r\n  File \"/usr/lib/python2.6/site-packages/genomedata/_load_seq.py\", line 261, in load_seq\r\n\r\n    read_seq(chromosome, seq)\r\n\r\n  File \"/usr/lib/python2.6/site-packages/genomedata/_load_seq.py\", line 133, in read_seq\r\n\r\n    seq_unambig, *span)\r\n\r\n  File \"/usr/lib/python2.6/site-packages/genomedata/_load_seq.py\", line 76, in create_supercontig\r\n\r\n    supercontig = h5file.createGroup(where, name)\r\n\r\n  File \"/usr/lib64/python2.6/site-packages/tables/_past.py\", line 35, in oldfunc\r\n\r\n    return obj(*args, **kwargs)\r\n\r\n  File \"/usr/lib64/python2.6/site-packages/tables/file.py\", line 959, in create_group\r\n\r\n    title=title, new=True, filters=filters)\r\n\r\n  File \"/usr/lib64/python2.6/site-packages/tables/group.py\", line 241, in __init__\r\n\r\n    super(Group, self).__init__(parentnode, name, _log)\r\n\r\n  File \"/usr/lib64/python2.6/site-packages/tables/node.py\", line 260, in __init__\r\n\r\n    parentnode._g_refnode(self, name, validate)\r\n\r\n  File \"/usr/lib64/python2.6/site-packages/tables/group.py\", line 529, in _g_refnode\r\n\r\n    % (self._v_pathname, childname))\r\n\r\ntables.exceptions.NodeError: group ``/`` already has a child node named ``supercontig_0``\r\n\r\n```", "markup": "markdown", "html": "<p>While incorrectly creating a genomedata archive, a non-descript error message was reported. A more useful error message should indicate what went wrong.</p>\n<p>The following command and problem was reported:</p>\n<div class=\"codehilite\"><pre><span></span>genomedata-load \u2013s sequence1.fa \u2013s sequence2.fa \u2013s sequence3.fa \u2013s sequence4.fa \u2013s sequence5.fa \u2013s sequence6.fa \u2013s sequence7.fa \u2013s sequence8.fa \u2013t track1=signal1.wigFix \u2013t track2=signal2. wigFix \u2013t track3=signal3. wigFix \u2013t track4=signal4. wigFix \u2013t track5=signal5. wigFix \u2013t track6=signal6. wigFix \u2013t track7=signal7. wigFix \u2013t track8=signal8. wigFix gtest\n</pre></div>\n\n\n<p>And I got the following message:</p>\n<div class=\"codehilite\"><pre><span></span>Error creating genomedata.\n\nTraceback (most recent call last):\n\n  File &quot;/usr/bin/genomedata-load&quot;, line 9, in &lt;module&gt;\n\n    load_entry_point(&#39;genomedata==1.3.5&#39;, &#39;console_scripts&#39;, &#39;genomedata-load&#39;)()\n\n  File &quot;/usr/lib/python2.6/site-packages/genomedata/load_genomedata.py&quot;, line 276, in main\n\n    seqfile_type=options.seqfile_type, **kwargs)\n\n  File &quot;/usr/lib/python2.6/site-packages/genomedata/load_genomedata.py&quot;, line 100, in load_genomedata\n\n    seqfile_type=seqfile_type)\n\n  File &quot;/usr/lib/python2.6/site-packages/genomedata/_load_seq.py&quot;, line 261, in load_seq\n\n    read_seq(chromosome, seq)\n\n  File &quot;/usr/lib/python2.6/site-packages/genomedata/_load_seq.py&quot;, line 133, in read_seq\n\n    seq_unambig, *span)\n\n  File &quot;/usr/lib/python2.6/site-packages/genomedata/_load_seq.py&quot;, line 76, in create_supercontig\n\n    supercontig = h5file.createGroup(where, name)\n\n  File &quot;/usr/lib64/python2.6/site-packages/tables/_past.py&quot;, line 35, in oldfunc\n\n    return obj(*args, **kwargs)\n\n  File &quot;/usr/lib64/python2.6/site-packages/tables/file.py&quot;, line 959, in create_group\n\n    title=title, new=True, filters=filters)\n\n  File &quot;/usr/lib64/python2.6/site-packages/tables/group.py&quot;, line 241, in __init__\n\n    super(Group, self).__init__(parentnode, name, _log)\n\n  File &quot;/usr/lib64/python2.6/site-packages/tables/node.py&quot;, line 260, in __init__\n\n    parentnode._g_refnode(self, name, validate)\n\n  File &quot;/usr/lib64/python2.6/site-packages/tables/group.py&quot;, line 529, in _g_refnode\n\n    % (self._v_pathname, childname))\n\ntables.exceptions.NodeError: group ``/`` already has a child node named ``supercontig_0``\n</pre></div>", "type": "rendered"}, "assignee": {"display_name": "Eric Roberts", "uuid": "{cd8c1fe0-28ca-45fb-8ef9-48090b42bb80}", "links": {"self": {"href": "https://api.bitbucket.org/2.0/users/%7Bcd8c1fe0-28ca-45fb-8ef9-48090b42bb80%7D"}, "html": {"href": "https://bitbucket.org/%7Bcd8c1fe0-28ca-45fb-8ef9-48090b42bb80%7D/"}, "avatar": {"href": "data/secure.gravatar.com/avatar/17548d71dfb29d015b880f48cfc01ca3d=httpsavatar-management--avatars.us-west-2.prod.public.atl-paas.netinitialsER-5.png"}}, "nickname": "ericr86", "type": "user", "account_id": "557058:c80ca578-03a1-4ac6-b3ee-50372a3fceee"}, "state": "new", "version": null, "edited_on": null, "created_on": "2014-11-13T18:30:48.780185+00:00", "milestone": null, "updated_on": "2014-11-13T18:31:39.734202+00:00", "type": "issue", "id": 14}