{"priority": "major", "kind": "bug", "repository": {"links": {"self": {"href": "data/repositories/hoffmanlab/genomedata.json"}, "html": {"href": "#!/hoffmanlab/genomedata"}, "avatar": {"href": "data/bytebucket.org/ravatar/{78038659-1199-46ff-9d0a-675c62f89d60}ts=python"}}, "type": "repository", "name": "genomedata", "full_name": "hoffmanlab/genomedata", "uuid": "{78038659-1199-46ff-9d0a-675c62f89d60}"}, "links": {"attachments": {"href": "data/repositories/hoffmanlab/genomedata/issues/21/attachments_page=1.json"}, "self": {"href": "data/repositories/hoffmanlab/genomedata/issues/21.json"}, "watch": {"href": "https://api.bitbucket.org/2.0/repositories/hoffmanlab/genomedata/issues/21/watch"}, "comments": {"href": "data/repositories/hoffmanlab/genomedata/issues/21/comments_page=1.json"}, "html": {"href": "#!/hoffmanlab/genomedata/issues/21/genomedata-open-data-plural-usage-of"}, "vote": {"href": "https://api.bitbucket.org/2.0/repositories/hoffmanlab/genomedata/issues/21/vote"}}, "reporter": {"display_name": "Eric Roberts", "uuid": "{cd8c1fe0-28ca-45fb-8ef9-48090b42bb80}", "links": {"self": {"href": "https://api.bitbucket.org/2.0/users/%7Bcd8c1fe0-28ca-45fb-8ef9-48090b42bb80%7D"}, "html": {"href": "https://bitbucket.org/%7Bcd8c1fe0-28ca-45fb-8ef9-48090b42bb80%7D/"}, "avatar": {"href": "data/secure.gravatar.com/avatar/17548d71dfb29d015b880f48cfc01ca3d=httpsavatar-management--avatars.us-west-2.prod.public.atl-paas.netinitialsER-5.png"}}, "nickname": "ericr86", "type": "user", "account_id": "557058:c80ca578-03a1-4ac6-b3ee-50372a3fceee"}, "title": "genomedata-open-data plural usage of trackname", "component": null, "votes": 0, "watches": 1, "content": {"raw": "As reported on the Segway-users mailing list:\r\n\r\nHi,\r\n\r\nAfter I installed the 1.3.6 version of genomedata, I did genomedata-load-seq first.\r\nThen when I do genomedata-open-data, with following option, I get an error:\r\n\r\n[zous3@noble-web encode_svn_phrase3]$ genomedata-open-data /net/noble/vol2/home/zous3/shiqi/encode_svn_phrase3/data/genomedata.data --trackname DNase-seq         \r\n\r\nTraceback (most recent call last):\r\n\r\n  File \"/net/noble/vol2/home/zous3/.local/bin/genomedata-open-data\", line 9, in <module>\r\n\r\n    load_entry_point('genomedata==1.3.6.dev-r0', 'console_scripts', 'genomedata-open-data')()\r\n\r\n  File \"/net/noble/vol2/home/zous3/.local/lib/python2.7/site-packages/genomedata-1.3.6.dev_r0-py2.7.egg/genomedata/_open_data.py\", line 52, in main\r\n\r\n    return open_data(args.gdarchive, args.tracknames, verbose=args.verbose)\r\n\r\nAttributeError: 'Namespace' object has no attribute 'tracknames'\r\n\r\n\r\nAfter going in the genomadata, inside /genomedata/_open_data.py , we changed\r\n\r\n      return open_data(args.gdarchive, args.tracknames, verbose=args.verbose)\r\n\r\nto\r\n\r\n      return open_data(args.gdarchive, args.trackname, verbose=args.verbose)\r\n\r\n, we deleted the \"s\" in 'tracknames', then it works.\r\n\r\n\r\nSo there is a inconsistent between the code and the documents, since the document said that \"usage: genomedata-open-data [-h] [-v] --trackname TRACKNAME [TRACKNAME ...][--verbose] gdarchive\"\r\n\r\n\r\nBest,\r\n\r\nShiqi", "markup": "markdown", "html": "<p>As reported on the Segway-users mailing list:</p>\n<p>Hi,</p>\n<p>After I installed the 1.3.6 version of genomedata, I did genomedata-load-seq first.\nThen when I do genomedata-open-data, with following option, I get an error:</p>\n<p>[zous3@noble-web encode_svn_phrase3]$ genomedata-open-data /net/noble/vol2/home/zous3/shiqi/encode_svn_phrase3/data/genomedata.data --trackname DNase-seq         </p>\n<p>Traceback (most recent call last):</p>\n<p>File \"/net/noble/vol2/home/zous3/.local/bin/genomedata-open-data\", line 9, in &lt;module&gt;</p>\n<div class=\"codehilite\"><pre><span></span>load_entry_point(&#39;genomedata==1.3.6.dev-r0&#39;, &#39;console_scripts&#39;, &#39;genomedata-open-data&#39;)()\n</pre></div>\n\n\n<p>File \"/net/noble/vol2/home/zous3/.local/lib/python2.7/site-packages/genomedata-1.3.6.dev_r0<a href=\"http://-py2.7.egg/genomedata/_open_data.py\" rel=\"nofollow\" class=\"ap-connect-link\">-py2.7.egg/genomedata/_open_data.py</a>\", line 52, in main</p>\n<div class=\"codehilite\"><pre><span></span>return open_data(args.gdarchive, args.tracknames, verbose=args.verbose)\n</pre></div>\n\n\n<p>AttributeError: 'Namespace' object has no attribute 'tracknames'</p>\n<p>After going in the genomadata, inside /genomedata/_open_data.py , we changed</p>\n<div class=\"codehilite\"><pre><span></span>  return open_data(args.gdarchive, args.tracknames, verbose=args.verbose)\n</pre></div>\n\n\n<p>to</p>\n<div class=\"codehilite\"><pre><span></span>  return open_data(args.gdarchive, args.trackname, verbose=args.verbose)\n</pre></div>\n\n\n<p>, we deleted the \"s\" in 'tracknames', then it works.</p>\n<p>So there is a inconsistent between the code and the documents, since the document said that \"usage: genomedata-open-data [-h] [-v] --trackname TRACKNAME [TRACKNAME ...][--verbose] gdarchive\"</p>\n<p>Best,</p>\n<p>Shiqi</p>", "type": "rendered"}, "assignee": {"display_name": "Eric Roberts", "uuid": "{cd8c1fe0-28ca-45fb-8ef9-48090b42bb80}", "links": {"self": {"href": "https://api.bitbucket.org/2.0/users/%7Bcd8c1fe0-28ca-45fb-8ef9-48090b42bb80%7D"}, "html": {"href": "https://bitbucket.org/%7Bcd8c1fe0-28ca-45fb-8ef9-48090b42bb80%7D/"}, "avatar": {"href": "data/secure.gravatar.com/avatar/17548d71dfb29d015b880f48cfc01ca3d=httpsavatar-management--avatars.us-west-2.prod.public.atl-paas.netinitialsER-5.png"}}, "nickname": "ericr86", "type": "user", "account_id": "557058:c80ca578-03a1-4ac6-b3ee-50372a3fceee"}, "state": "new", "version": null, "edited_on": null, "created_on": "2016-04-13T19:54:08.006761+00:00", "milestone": null, "updated_on": "2016-04-13T19:54:08.006761+00:00", "type": "issue", "id": 21}