{"priority": "major", "kind": "bug", "repository": {"links": {"self": {"href": "data/repositories/hoffmanlab/genomedata.json"}, "html": {"href": "#!/hoffmanlab/genomedata"}, "avatar": {"href": "data/bytebucket.org/ravatar/{78038659-1199-46ff-9d0a-675c62f89d60}ts=python"}}, "type": "repository", "name": "genomedata", "full_name": "hoffmanlab/genomedata", "uuid": "{78038659-1199-46ff-9d0a-675c62f89d60}"}, "links": {"attachments": {"href": "data/repositories/hoffmanlab/genomedata/issues/41/attachments_page=1.json"}, "self": {"href": "data/repositories/hoffmanlab/genomedata/issues/41.json"}, "watch": {"href": "https://api.bitbucket.org/2.0/repositories/hoffmanlab/genomedata/issues/41/watch"}, "comments": {"href": "data/repositories/hoffmanlab/genomedata/issues/41/comments_page=1.json"}, "html": {"href": "#!/hoffmanlab/genomedata/issues/41/genomedata-load-seq-error"}, "vote": {"href": "https://api.bitbucket.org/2.0/repositories/hoffmanlab/genomedata/issues/41/vote"}}, "reporter": null, "title": "genomedata-load-seq error", "component": null, "votes": 0, "watches": null, "content": {"raw": "When I run genomedata-load-seq using the following command:\r\n\r\ngenomedata-load-seq -f embl87Galgal5.genomedata embl87Galgal5.dna.fa\r\n\r\nI got the following error message:\r\n\r\nTraceback (most recent call last):\r\n  File \"/usr/local/bin/genomedata-load-seq\", line 9, in <module>\r\n    load_entry_point('genomedata==1.3.6', 'console_scripts', 'genomedata-load-seq')()\r\n  File \"/usr/local/lib/python2.7/dist-packages/genomedata/_load_seq.py\", line 319, in main\r\n    mode=args.mode, seqfile_type=args.seqfile_type)\r\n  File \"/usr/local/lib/python2.7/dist-packages/genomedata/_load_seq.py\", line 233, in load_seq\r\n    assert not gdpath.exists()\r\nAssertionError", "markup": "markdown", "html": "<p>When I run genomedata-load-seq using the following command:</p>\n<p>genomedata-load-seq -f embl87Galgal5.genomedata embl87Galgal5.dna.fa</p>\n<p>I got the following error message:</p>\n<p>Traceback (most recent call last):\n  File \"/usr/local/bin/genomedata-load-seq\", line 9, in &lt;module&gt;\n    load_entry_point('genomedata==1.3.6', 'console_scripts', 'genomedata-load-seq')()\n  File \"/usr/local/lib/python2.7/dist-packages/genomedata/_load_seq.py\", line 319, in main\n    mode=args.mode, seqfile_type=args.seqfile_type)\n  File \"/usr/local/lib/python2.7/dist-packages/genomedata/_load_seq.py\", line 233, in load_seq\n    assert not gdpath.exists()\nAssertionError</p>", "type": "rendered"}, "assignee": null, "state": "new", "version": null, "edited_on": null, "created_on": "2017-08-26T22:18:52.597649+00:00", "milestone": null, "updated_on": "2017-08-28T18:12:34.904278+00:00", "type": "issue", "id": 41}