{"priority": "trivial", "kind": "bug", "repository": {"links": {"self": {"href": "data/repositories/hoffmanlab/genomedata.json"}, "html": {"href": "#!/hoffmanlab/genomedata"}, "avatar": {"href": "data/bytebucket.org/ravatar/{78038659-1199-46ff-9d0a-675c62f89d60}ts=python"}}, "type": "repository", "name": "genomedata", "full_name": "hoffmanlab/genomedata", "uuid": "{78038659-1199-46ff-9d0a-675c62f89d60}"}, "links": {"attachments": {"href": "data/repositories/hoffmanlab/genomedata/issues/50/attachments_page=1.json"}, "self": {"href": "data/repositories/hoffmanlab/genomedata/issues/50.json"}, "watch": {"href": "https://api.bitbucket.org/2.0/repositories/hoffmanlab/genomedata/issues/50/watch"}, "comments": {"href": "data/repositories/hoffmanlab/genomedata/issues/50/comments_page=1.json"}, "html": {"href": "#!/hoffmanlab/genomedata/issues/50/pip-install-upgrade-genomedata-can-fail-on"}, "vote": {"href": "https://api.bitbucket.org/2.0/repositories/hoffmanlab/genomedata/issues/50/vote"}}, "reporter": {"display_name": "Coby Viner", "uuid": "{5c0277b2-d18f-432a-9ff0-3377d3063bd6}", "links": {"self": {"href": "https://api.bitbucket.org/2.0/users/%7B5c0277b2-d18f-432a-9ff0-3377d3063bd6%7D"}, "html": {"href": "https://bitbucket.org/%7B5c0277b2-d18f-432a-9ff0-3377d3063bd6%7D/"}, "avatar": {"href": "data/secure.gravatar.com/avatar/30ee4699432a3591c043fbe3d4bff771d=httpsavatar-management--avatars.us-west-2.prod.public.atl-paas.netinitialsCV-5.png"}}, "nickname": "cviner2", "type": "user", "account_id": "557058:278c659b-177a-486c-bf20-6982986d7e43"}, "title": "pip install --upgrade genomedata can fail on some systems, due to path.py issues", "component": null, "votes": 0, "watches": 1, "content": {"raw": "On  [Graham](https://docs.computecanada.ca/wiki/Graham), I had version 1.3.6 installed via `pip install --user genomedata`.\r\n\r\nUpon upgrading, via `pip install --user --upgrade genomedata`, to version 1.4.4, I was no longer able to use genomedata, obtaining:\r\n\r\n```\r\n#!text\r\n\r\nTraceback (most recent call last):\r\n  File \"../../src/cytomod.py\", line 673, in <module>\r\n    from genomedata import Genome, load_genomedata\r\n  File \"/home/cviner2/.local/lib/python2.7/site-packages/genomedata/__init__.py\", line 29, in <module>\r\n    from path import path\r\nImportError: cannot import name path\r\n```\r\n\r\nThis occurred with `path.py` 11.5.0, which was automatically installed. Downgrading to version 8.2.1 restored functionality, at least with respect to this single command. Uninstalling and reinstalling `path.py` manually, to the latest version (11.5.0) also appeared to resolve this, but other modules may have been upgraded in between doing so (unfortunately I cannot reproduce this part).\r\n\r\nRelatedly, something similar appears to be a [common](https://stackoverflow.com/a/32254055/5339699) [issue](https://github.com/pickleshare/pickleshare/issues/8) with `path.py`, though not directly involving these versions or workflow. It might be a good idea to (somehow) force a reinstall of `path.py` or perhaps just to document this as a potential issue with the above possible solution?", "markup": "markdown", "html": "<p>On  <a data-is-external-link=\"true\" href=\"https://docs.computecanada.ca/wiki/Graham\" rel=\"nofollow\">Graham</a>, I had version 1.3.6 installed via <code>pip install --user genomedata</code>.</p>\n<p>Upon upgrading, via <code>pip install --user --upgrade genomedata</code>, to version 1.4.4, I was no longer able to use genomedata, obtaining:</p>\n<div class=\"codehilite language-text\"><pre><span></span>Traceback (most recent call last):\n  File &quot;../../src/cytomod.py&quot;, line 673, in &lt;module&gt;\n    from genomedata import Genome, load_genomedata\n  File &quot;/home/cviner2/.local/lib/python2.7/site-packages/genomedata/__init__.py&quot;, line 29, in &lt;module&gt;\n    from path import path\nImportError: cannot import name path\n</pre></div>\n\n\n<p>This occurred with <code>path.py</code> 11.5.0, which was automatically installed. Downgrading to version 8.2.1 restored functionality, at least with respect to this single command. Uninstalling and reinstalling <code>path.py</code> manually, to the latest version (11.5.0) also appeared to resolve this, but other modules may have been upgraded in between doing so (unfortunately I cannot reproduce this part).</p>\n<p>Relatedly, something similar appears to be a <a data-is-external-link=\"true\" href=\"https://stackoverflow.com/a/32254055/5339699\" rel=\"nofollow\">common</a> <a data-is-external-link=\"true\" href=\"https://github.com/pickleshare/pickleshare/issues/8\" rel=\"nofollow\">issue</a> with <code>path.py</code>, though not directly involving these versions or workflow. It might be a good idea to (somehow) force a reinstall of <code>path.py</code> or perhaps just to document this as a potential issue with the above possible solution?</p>", "type": "rendered"}, "assignee": null, "state": "new", "version": null, "edited_on": null, "created_on": "2019-01-02T22:12:51.830683+00:00", "milestone": null, "updated_on": "2019-02-24T21:48:26.518098+00:00", "type": "issue", "id": 50}